Workbook

Sheet README
A1: Proud Tek 2026 RFID Industry Adoption Index
A2: Survey Instrument workbook
A4: Pre-registered | B4: 2026-05-11
A5: Version | B5: 1.0
A6: Owner | B6: ProudTek Editorial Board / Peter Zhang
A8: Sheet | B8: Purpose
A9: README | B9: This sheet.
A10: Question Bank | B10: 25 common-stem questions + 100 industry-specific questions (5 × 20 industries). Each row carries question text, type, scale/options, rationale, and which research question / hypothesis it addresses.
A11: Industry Blocks Map | B11: Which Q3 industry response triggers which 5-item industry block.
A12: Respondent DB | B12: Recruitment funnel tracker. 200 row slots, channel + status + dates. Formula columns at the top show live funnel counts.
A13: Raw Data | B13: Template with one row per respondent. Columns mirror QIDs. Column headers carry the QID. Drop survey-export CSV here.
A14: Analysis Cross-tabs | B14: Pre-registered cross-tabs. Each is a placeholder formula against Raw Data. Update Raw Data → cross-tabs refresh.
A15: Dashboard | B15: Top-line statistics. Adoption stage by industry, mandate progress, KPI lift expected-vs-realized, 2027 intent. Live formulas.
A16: Methodology Metadata | B16: Sample sizes, response rates, weighting target (IDC), exclusion rules, conflict-of-interest register.
A19: How to use this workbook
A20: 1. | B20: Recruitment team uses Respondent DB to track every outreach attempt. Formulas roll up daily into the funnel counters at the top of the sheet.
A21: 2. | B21: Field operations exports the Qualtrics CSV at fieldwork close and pastes into Raw Data, preserving the QID column order.
A22: 3. | B22: Analysis Cross-tabs and Dashboard auto-refresh against Raw Data. Pre-registered analyses (RQ1–RQ5) are labeled; exploratory analyses are clearly labeled separately.
A23: 4. | B23: Methodology Metadata is updated as response rates land. Final values are copied into the report methodology appendix.

Sheet Question Bank
A1: QID | B1: Section | C1: Question | D1: Type | E1: Scale / options | F1: Rationale | G1: Maps to
A2: Q1 | B2: Screening | C2: What industry best describes your organization? | D2: Single-choice | E2: 20 industries (one of) | F2: Industry stratification + branching to industry-specific block. | G2: RQ1, RQ2, RQ3, RQ4, RQ5
A3: Q2 | B3: Screening | C3: Which role describes you best? | D3: Single-choice | E3: Procurement / IT / Operations / Supply chain / Compliance / Other | F3: Role band for analysis weighting. | G3: Secondary
A4: Q3 | B4: Screening | C4: What is your organization's annual revenue band? | D4: Single-choice | E4: <$10M / $10–50M / $50–250M / $250M–1B / >$1B | F4: Organization-size weighting cell. | G4: All
A5: Q4 | B5: Adoption maturity | C5: What stage best describes your organization's RFID/NFC deployment? | D5: Single-choice | E5: No RFID / Piloting / Partial production / Full production | F5: Primary RQ1 outcome. | G5: RQ1, RQ5
A6: Q5 | B6: Adoption maturity | C6: In what year did you first deploy RFID/NFC in production? | D6: Numeric | E6: Year 2000–2026 or 'not yet' | F6: Tenure-of-deployment cross-tab. | G6: RQ1
A7: Q6 | B7: Adoption maturity | C7: What is the scope of your deployment? | D7: Multi-select | E7: Item-level / Case / Pallet / Asset tracking / Access control / Customer engagement / Other | F7: Scope breadth. | G7: RQ1, RQ4
A8: Q7 | B8: Adoption maturity | C8: Which frequency band(s) do you use? | D8: Multi-select | E8: LF (125 kHz) / HF (13.56 MHz) / NFC / UHF (860–960 MHz) | F8: Frequency mix per industry. | G8: RQ1, RQ4
A9: Q8 | B9: Spend | C9: Approximate total RFID/NFC tag spend in the last 12 months? | D9: Single-choice | E9: <$10K / $10–100K / $100K–500K / $500K–2M / >$2M | F9: Spend bands. | G9: Secondary
A10: Q9 | B10: Spend | C10: Projected RFID/NFC tag spend in the next 12 months? | D10: Single-choice | E10: Same bands as Q8 + Don't know | F10: Forward-looking spend signal. | G10: RQ5
A11: Q10 | B11: Spend | C11: What is your primary RFID hardware supplier (tags/labels/cards)? | D11: Open-text | E11: Free text, normalized in cleaning | F11: Vendor consolidation analysis. | G11: RQ4
A12: Q11 | B12: Spend | C12: How many distinct hardware vendors are in your RFID footprint? | D12: Single-choice | E12: 1 / 2 / 3 / 4 / 5+ | F12: Vendor consolidation level. | G12: RQ4
... A26: Q25 | B26: Open | C26: What is the single biggest barrier to RFID expansion in your organization right now? | D26: Open-text | E26: Free text, 500 char cap | F26: Themes for qualitative analysis. | G26: Secondary
A27: --- Industry-specific blocks (triggered by Q1) ---
A28: RETAIL & APPAREL
A29: RA1 | B29: Industry block — Retail & Apparel | C29: Which retailer mandates does your organization currently comply with? | D29: Multi-select | E29: Walmart T1 / T2 / T3 / Target SUPPLIERS / Macy's / Nordstrom / Inditex / H&M / Lululemon / Decathlon / None | F29: Tier-specific mandate mapping. | G29: Industry-specific
A30: RA2 | B30: Industry block — Retail & Apparel | C30: Are your inlays Auburn ARC certified? | D30: Single-choice | E30: Yes — A/B/C/M/T/U/W/X / No / Don't know | F30: Auburn ARC awareness + status. | G30: Industry-specific
A31: RA3 | B31: Industry block — Retail & Apparel | C31: Where is source-tagging applied? | D31: Single-choice | E31: Factory / DC retrofit / Mix / Not yet source-tagging | F31: Source-tag vs retrofit split. | G31: Industry-specific
A32: RA4 | B32: Industry block — Retail & Apparel | C32: Post-deployment, your BOPIS fulfilment lift was... | D32: Numeric | E32: % from baseline | F32: BOPIS lift specific to retail. | G32: Industry-specific
A33: RA5 | B33: Industry block — Retail & Apparel | C33: Form-factor mix in your apparel deployment? | D33: Allocation 100% | E33: Hang tag / Woven label / Printable label / Other | F33: Apparel form-factor distribution. | G33: Industry-specific
A34: HOSPITALITY
A35: HO1 | B35: Industry block — Hospitality | C35: Which physical-access vendor's locks do you operate? | D35: Single-choice | E35: Saflok / VingCard / Salto / dormakaba / Onity / Mix / Other | F35: Lock-vendor distribution. | G35: Industry-specific
A36: HO2 | B36: Industry block — Hospitality | C36: DESFire EV3 migration status? | D36: Single-choice | E36: Not started / Pilot / Partial / Fully migrated / N/A (Classic only) | F36: DESFire migration. | G36: Industry-specific
A37: HO3 | B37: Industry block — Hospitality | C37: NFC cashless adoption in property? | D37: Single-choice | E37: None / Pilot / Partial / Full | F37: Cashless deployment. | G37: Industry-specific
A38: HO4 | B38: Industry block — Hospitality | C38: Linen / textile RFID deployment status? | D38: Single-choice | E38: None / Pilot / Partial / Full | F38: Linen tracking. | G38: Industry-specific
A39: HO5 | B39: Industry block — Hospitality | C39: Have you migrated from magnetic-stripe to MIFARE-based keys? | D39: Single-choice | E39: Fully migrated / In progress / Not started / N/A | F39: Magstripe sunset. | G39: Industry-specific
A40: HEALTHCARE
A41: HC1 | B41: Industry block — Healthcare | C41: Which clinical workflow uses RFID/NFC? | D41: Multi-select | E41: Patient ID wristbands / Specimen tracking / Blood-bag tracking / Surgical-instrument tagging / Medication / Asset tracking / Access control / None | F41: Workflow coverage. | G41: Industry-specific
A42: HC2 | B42: Industry block — Healthcare | C42: Are your patient wristbands HF (ISO 14443/15693) or UHF? | D42: Single-choice | E42: HF / UHF / Both / Don't know / N/A | F42: Frequency for patient ID. | G42: Industry-specific
A43: HC3 | B43: Industry block — Healthcare | C43: HIPAA / FDA 21 CFR Part 11 audit-trail readiness for RFID-touched workflows? | D43: Likert-5 | E43: 1 = none, 5 = audit-ready | F43: Compliance readiness. | G43: Industry-specific
A44: HC4 | B44: Industry block — Healthcare | C44: Surgical-instrument reprocessing — RFID tracking deployed? | D44: Single-choice | E44: Yes — fully / Yes — partial / No, considering / No | F44: Surgical reprocessing. | G44: Industry-specific
A45: HC5 | B45: Industry block — Healthcare | C45: Are you using DSCSA-compliant carriers for in-pharmacy unit dispensing? | D45: Single-choice | E45: Yes — RFID / Yes — barcode / Both / No / N/A | F45: DSCSA at dispense. | G45: Industry-specific
A46: EVENTS & VENUES
A47: EV1 | B47: Industry block — Events & Venues | C47: Type of venue. | D47: Single-choice | E47: Festival / Stadium / Arena / Theme park / Conference / Convention center / Casino / Other | F47: Venue type. | G47: Industry-specific
A48: EV2 | B48: Industry block — Events & Venues | C48: Cashless wristband / token spend as % of total venue spend? | D48: Single-choice | E48: 0% / 1–25% / 26–50% / 51–75% / 76–100% | F48: Cashless penetration. | G48: Industry-specific
A49: EV3 | B49: Industry block — Events & Venues | C49: Average per-capita spend lift on cashless vs cash? | D49: Single-choice | E49: 0% / 1–10% / 11–20% / 21–30% / >30% / Don't measure | F49: Spend-lift measurement. | G49: Industry-specific
A50: EV4 | B50: Industry block — Events & Venues | C50: Wristband technology used. | D50: Multi-select | E50: HF / UHF / Dual / NFC / None — paper | F50: Technology mix. | G50: Industry-specific
A51: EV5 | B51: Industry block — Events & Venues | C51: Integration with ticketing platform? | D51: Single-choice | E51: Tappit / Connect&GO / Intellitix / Patron / Custom / None | F51: Platform vendor. | G51: Industry-specific
A52: LOGISTICS
A53: LO1 | B53: Industry block — Logistics | C53: What is your primary RFID use case? | D53: Multi-select | E53: Pallet / Case / Returnable transport items / Yard mgmt / Trailer-loading verification / Baggage (IATA 753) / Other | F53: Use-case mix. | G53: Industry-specific
...

Sheet Industry Blocks Map
A1: Q1 industry response | B1: Triggered block | C1: Item count | D1: QID prefix
A2: Retail & Apparel | B2: Retail & Apparel block | C2: 5 | D2: RA
A3: Hospitality | B3: Hospitality block | C3: 5 | D3: HO
A4: Healthcare | B4: Healthcare block | C4: 5 | D4: HC
A5: Events & Venues | B5: Events & Venues block | C5: 5 | D5: EV
A6: Logistics | B6: Logistics block | C6: 5 | D6: LO
A7: Industrial | B7: Industrial block | C7: 5 | D7: IN
A8: Libraries | B8: Libraries block | C8: 5 | D8: LI
A9: Laundry Services | B9: Laundry Services block | C9: 5 | D9: LA
A10: Pharmaceutical | B10: Pharmaceutical block | C10: 5 | D10: PH
A11: Luxury Brands | B11: Luxury Brands block | C11: 5 | D11: LU
A12: Brand Protection | B12: Brand Protection block | C12: 5 | D12: BP
A13: Education | B13: Education block | C13: 5 | D13: ED
... A21: Cold Chain & Food Traceability | B21: Cold Chain & Food Traceability block | C21: 5 | D21: CC

Sheet Respondent DB
A1: Recruitment funnel — live counts
A3: Target N | B3: 200
A4: Invited | B4: =COUNTIF(I:I, "Invited")+COUNTIF(I:I, "Reminded")+COUNTIF(I:I, "Qualified")+COUNTIF(I:I, "Completed")+COUNTIF(I:I, "Excluded") -> 1
A5: Qualified | B5: =COUNTIF(I:I, "Qualified")+COUNTIF(I:I, "Completed") -> 0
A6: Completed | B6: =COUNTIF(I:I, "Completed") -> 0
A7: Excluded | B7: =COUNTIF(I:I, "Excluded") -> 0
A8: Response rate | B8: =IFERROR(B5/B3, 0) -> 0
A10: Respondent ID | B10: Date invited | C10: Channel | D10: Industry (Q1) | E10: Role (Q2) | F10: Org-size (Q3) | G10: Org domain | H10: Reminder count | I10: Status | J10: Date completed | K10: Exclusion reason | L10: Incentive paid | N10: Industry quota | O10: Completed | P10: Target | Q10: % to goal
A11: R0001 | B11: 2026-05-18 | C11: LinkedIn Sales Nav | D11: Retail & Apparel | E11: Procurement | F11: $250M–1B | G11: example.com | H11: 0 | I11: Invited | N11: Retail & Apparel | O11: =COUNTIFS(D:D,"Retail & Apparel",I:I,"Completed") -> 0 | P11: 10 | Q11: =IFERROR(O11/P11, 0) -> 0
N12: Hospitality | O12: =COUNTIFS(D:D,"Hospitality",I:I,"Completed") -> 0 | P12: 10 | Q12: =IFERROR(O12/P12, 0) -> 0
N13: Healthcare | O13: =COUNTIFS(D:D,"Healthcare",I:I,"Completed") -> 0 | P13: 10 | Q13: =IFERROR(O13/P13, 0) -> 0
N14: Events & Venues | O14: =COUNTIFS(D:D,"Events & Venues",I:I,"Completed") -> 0 | P14: 10 | Q14: =IFERROR(O14/P14, 0) -> 0
N15: Logistics | O15: =COUNTIFS(D:D,"Logistics",I:I,"Completed") -> 0 | P15: 10 | Q15: =IFERROR(O15/P15, 0) -> 0
N16: Industrial | O16: =COUNTIFS(D:D,"Industrial",I:I,"Completed") -> 0 | P16: 10 | Q16: =IFERROR(O16/P16, 0) -> 0
N17: Libraries | O17: =COUNTIFS(D:D,"Libraries",I:I,"Completed") -> 0 | P17: 10 | Q17: =IFERROR(O17/P17, 0) -> 0
N18: Laundry Services | O18: =COUNTIFS(D:D,"Laundry Services",I:I,"Completed") -> 0 | P18: 10 | Q18: =IFERROR(O18/P18, 0) -> 0
N19: Pharmaceutical | O19: =COUNTIFS(D:D,"Pharmaceutical",I:I,"Completed") -> 0 | P19: 10 | Q19: =IFERROR(O19/P19, 0) -> 0
N20: Luxury Brands | O20: =COUNTIFS(D:D,"Luxury Brands",I:I,"Completed") -> 0 | P20: 10 | Q20: =IFERROR(O20/P20, 0) -> 0
N21: Brand Protection | O21: =COUNTIFS(D:D,"Brand Protection",I:I,"Completed") -> 0 | P21: 10 | Q21: =IFERROR(O21/P21, 0) -> 0
N22: Education | O22: =COUNTIFS(D:D,"Education",I:I,"Completed") -> 0 | P22: 10 | Q22: =IFERROR(O22/P22, 0) -> 0
N23: Fitness | O23: =COUNTIFS(D:D,"Fitness",I:I,"Completed") -> 0 | P23: 10 | Q23: =IFERROR(O23/P23, 0) -> 0
N24: Agriculture | O24: =COUNTIFS(D:D,"Agriculture",I:I,"Completed") -> 0 | P24: 10 | Q24: =IFERROR(O24/P24, 0) -> 0
N25: EU Compliance | O25: =COUNTIFS(D:D,"EU Compliance",I:I,"Completed") -> 0 | P25: 10 | Q25: =IFERROR(O25/P25, 0) -> 0
N26: Automotive & Tire OEM | O26: =COUNTIFS(D:D,"Automotive & Tire OEM",I:I,"Completed") -> 0 | P26: 10 | Q26: =IFERROR(O26/P26, 0) -> 0
N27: Aerospace & Aviation MRO | O27: =COUNTIFS(D:D,"Aerospace & Aviation MRO",I:I,"Completed") -> 0 | P27: 10 | Q27: =IFERROR(O27/P27, 0) -> 0
N28: Data Center & IT Asset Tracking | O28: =COUNTIFS(D:D,"Data Center & IT Asset Tracking",I:I,"Completed") -> 0 | P28: 10 | Q28: =IFERROR(O28/P28, 0) -> 0
N29: Government & Defense | O29: =COUNTIFS(D:D,"Government & Defense",I:I,"Completed") -> 0 | P29: 10 | Q29: =IFERROR(O29/P29, 0) -> 0
N30: Cold Chain & Food Traceability | O30: =COUNTIFS(D:D,"Cold Chain & Food Traceability",I:I,"Completed") -> 0 | P30: 10 | Q30: =IFERROR(O30/P30, 0) -> 0

Sheet Raw Data
A1: Raw Data — paste Qualtrics CSV export here at fieldwork close. Preserve QID column order.
A3: RespondentID | B3: ResponseDate | C3: Channel | D3: DurationSec | E3: Q1 | F3: Q2 | G3: Q3 | H3: Q4 | I3: Q5 | J3: Q6 | K3: Q7 | L3: Q8 | M3: Q9 | N3: Q10 | O3: Q11 | P3: Q12 | Q3: Q13 | R3: Q14 | S3: Q15 | T3: Q16 | U3: Q17 | V3: Q18 | W3: Q19 | X3: Q20 | Y3: Q21 | Z3: Q22 | AA3: Q23 | AB3: Q24 | AC3: Q25 | AD3: RA1 | AE3: RA2 | AF3: RA3 | AG3: RA4 | AH3: RA5 | AI3: HO1 | AJ3: HO2 | AK3: HO3 | AL3: HO4 | AM3: HO5 | AN3: HC1 | AO3: HC2 | AP3: HC3 | AQ3: HC4 | AR3: HC5 | AS3: EV1 | AT3: EV2 | AU3: EV3 | AV3: EV4 | AW3: EV5 | AX3: LO1 | AY3: LO2 | AZ3: LO3 | BA3: LO4 | BB3: LO5 | BC3: IN1 | BD3: IN2 | BE3: IN3 | BF3: IN4 | BG3: IN5 | BH3: LI1 | BI3: LI2 | BJ3: LI3 | BK3: LI4 | BL3: LI5 | BM3: LA1 | BN3: LA2 | BO3: LA3 | BP3: LA4 | BQ3: LA5 | BR3: PH1 | BS3: PH2 | BT3: PH3 | BU3: PH4 | BV3: PH5 | BW3: LU1 | BX3: LU2 | BY3: LU3 | BZ3: LU4 | CA3: LU5 | CB3: BP1 | CC3: BP2 | CD3: BP3 | CE3: BP4 | CF3: BP5 | CG3: ED1 | CH3: ED2 | CI3: ED3 | CJ3: ED4 | CK3: ED5 | CL3: FI1 | CM3: FI2 | CN3: FI3 | CO3: FI4 | CP3: FI5 | CQ3: AG1 | CR3: AG2 | CS3: AG3 | CT3: AG4 | CU3: AG5 | CV3: EU1 | CW3: EU2 | CX3: EU3 | CY3: EU4 | CZ3: EU5 | DA3: AT1 | DB3: AT2 | DC3: AT3 | DD3: AT4 | DE3: AT5 | DF3: AS1 | DG3: AS2 | DH3: AS3 | DI3: AS4 | DJ3: AS5 | DK3: DC1 | DL3: DC2 | DM3: DC3 | DN3: DC4 | DO3: DC5 | DP3: GD1 | DQ3: GD2 | DR3: GD3 | DS3: GD4 | DT3: GD5 | DU3: CC1 | DV3: CC2 | DW3: CC3 | DX3: CC4 | DY3: CC5

Sheet Analysis Cross-tabs
A1: Pre-registered analyses — formulas pull from Raw Data.
A2: Italic cells are placeholders the analyst replaces with run-specific formulas after data closes.
A4: RQ1 — Adoption maturity by industry (Q4)
A5: Industry | B5: No RFID | C5: Piloting | D5: Partial production | E5: Full production | F5: Total
A6: Retail & Apparel | B6: =COUNTIFS('Raw Data'!E:E,"Retail & Apparel",'Raw Data'!H:H,"No RFID") -> 0 | C6: =COUNTIFS('Raw Data'!E:E,"Retail & Apparel",'Raw Data'!H:H,"Piloting") -> 0 | D6: =COUNTIFS('Raw Data'!E:E,"Retail & Apparel",'Raw Data'!H:H,"Partial production") -> 0 | E6: =COUNTIFS('Raw Data'!E:E,"Retail & Apparel",'Raw Data'!H:H,"Full production") -> 0 | F6: =SUM(B6:E6) -> 0
A7: Hospitality | B7: =COUNTIFS('Raw Data'!E:E,"Hospitality",'Raw Data'!H:H,"No RFID") -> 0 | C7: =COUNTIFS('Raw Data'!E:E,"Hospitality",'Raw Data'!H:H,"Piloting") -> 0 | D7: =COUNTIFS('Raw Data'!E:E,"Hospitality",'Raw Data'!H:H,"Partial production") -> 0 | E7: =COUNTIFS('Raw Data'!E:E,"Hospitality",'Raw Data'!H:H,"Full production") -> 0 | F7: =SUM(B7:E7) -> 0
A8: Healthcare | B8: =COUNTIFS('Raw Data'!E:E,"Healthcare",'Raw Data'!H:H,"No RFID") -> 0 | C8: =COUNTIFS('Raw Data'!E:E,"Healthcare",'Raw Data'!H:H,"Piloting") -> 0 | D8: =COUNTIFS('Raw Data'!E:E,"Healthcare",'Raw Data'!H:H,"Partial production") -> 0 | E8: =COUNTIFS('Raw Data'!E:E,"Healthcare",'Raw Data'!H:H,"Full production") -> 0 | F8: =SUM(B8:E8) -> 0
A9: Events & Venues | B9: =COUNTIFS('Raw Data'!E:E,"Events & Venues",'Raw Data'!H:H,"No RFID") -> 0 | C9: =COUNTIFS('Raw Data'!E:E,"Events & Venues",'Raw Data'!H:H,"Piloting") -> 0 | D9: =COUNTIFS('Raw Data'!E:E,"Events & Venues",'Raw Data'!H:H,"Partial production") -> 0 | E9: =COUNTIFS('Raw Data'!E:E,"Events & Venues",'Raw Data'!H:H,"Full production") -> 0 | F9: =SUM(B9:E9) -> 0
A10: Logistics | B10: =COUNTIFS('Raw Data'!E:E,"Logistics",'Raw Data'!H:H,"No RFID") -> 0 | C10: =COUNTIFS('Raw Data'!E:E,"Logistics",'Raw Data'!H:H,"Piloting") -> 0 | D10: =COUNTIFS('Raw Data'!E:E,"Logistics",'Raw Data'!H:H,"Partial production") -> 0 | E10: =COUNTIFS('Raw Data'!E:E,"Logistics",'Raw Data'!H:H,"Full production") -> 0 | F10: =SUM(B10:E10) -> 0
A11: Industrial | B11: =COUNTIFS('Raw Data'!E:E,"Industrial",'Raw Data'!H:H,"No RFID") -> 0 | C11: =COUNTIFS('Raw Data'!E:E,"Industrial",'Raw Data'!H:H,"Piloting") -> 0 | D11: =COUNTIFS('Raw Data'!E:E,"Industrial",'Raw Data'!H:H,"Partial production") -> 0 | E11: =COUNTIFS('Raw Data'!E:E,"Industrial",'Raw Data'!H:H,"Full production") -> 0 | F11: =SUM(B11:E11) -> 0
A12: Libraries | B12: =COUNTIFS('Raw Data'!E:E,"Libraries",'Raw Data'!H:H,"No RFID") -> 0 | C12: =COUNTIFS('Raw Data'!E:E,"Libraries",'Raw Data'!H:H,"Piloting") -> 0 | D12: =COUNTIFS('Raw Data'!E:E,"Libraries",'Raw Data'!H:H,"Partial production") -> 0 | E12: =COUNTIFS('Raw Data'!E:E,"Libraries",'Raw Data'!H:H,"Full production") -> 0 | F12: =SUM(B12:E12) -> 0
A13: Laundry Services | B13: =COUNTIFS('Raw Data'!E:E,"Laundry Services",'Raw Data'!H:H,"No RFID") -> 0 | C13: =COUNTIFS('Raw Data'!E:E,"Laundry Services",'Raw Data'!H:H,"Piloting") -> 0 | D13: =COUNTIFS('Raw Data'!E:E,"Laundry Services",'Raw Data'!H:H,"Partial production") -> 0 | E13: =COUNTIFS('Raw Data'!E:E,"Laundry Services",'Raw Data'!H:H,"Full production") -> 0 | F13: =SUM(B13:E13) -> 0
A14: Pharmaceutical | B14: =COUNTIFS('Raw Data'!E:E,"Pharmaceutical",'Raw Data'!H:H,"No RFID") -> 0 | C14: =COUNTIFS('Raw Data'!E:E,"Pharmaceutical",'Raw Data'!H:H,"Piloting") -> 0 | D14: =COUNTIFS('Raw Data'!E:E,"Pharmaceutical",'Raw Data'!H:H,"Partial production") -> 0 | E14: =COUNTIFS('Raw Data'!E:E,"Pharmaceutical",'Raw Data'!H:H,"Full production") -> 0 | F14: =SUM(B14:E14) -> 0
A15: Luxury Brands | B15: =COUNTIFS('Raw Data'!E:E,"Luxury Brands",'Raw Data'!H:H,"No RFID") -> 0 | C15: =COUNTIFS('Raw Data'!E:E,"Luxury Brands",'Raw Data'!H:H,"Piloting") -> 0 | D15: =COUNTIFS('Raw Data'!E:E,"Luxury Brands",'Raw Data'!H:H,"Partial production") -> 0 | E15: =COUNTIFS('Raw Data'!E:E,"Luxury Brands",'Raw Data'!H:H,"Full production") -> 0 | F15: =SUM(B15:E15) -> 0
A16: Brand Protection | B16: =COUNTIFS('Raw Data'!E:E,"Brand Protection",'Raw Data'!H:H,"No RFID") -> 0 | C16: =COUNTIFS('Raw Data'!E:E,"Brand Protection",'Raw Data'!H:H,"Piloting") -> 0 | D16: =COUNTIFS('Raw Data'!E:E,"Brand Protection",'Raw Data'!H:H,"Partial production") -> 0 | E16: =COUNTIFS('Raw Data'!E:E,"Brand Protection",'Raw Data'!H:H,"Full production") -> 0 | F16: =SUM(B16:E16) -> 0
A17: Education | B17: =COUNTIFS('Raw Data'!E:E,"Education",'Raw Data'!H:H,"No RFID") -> 0 | C17: =COUNTIFS('Raw Data'!E:E,"Education",'Raw Data'!H:H,"Piloting") -> 0 | D17: =COUNTIFS('Raw Data'!E:E,"Education",'Raw Data'!H:H,"Partial production") -> 0 | E17: =COUNTIFS('Raw Data'!E:E,"Education",'Raw Data'!H:H,"Full production") -> 0 | F17: =SUM(B17:E17) -> 0
A18: Fitness | B18: =COUNTIFS('Raw Data'!E:E,"Fitness",'Raw Data'!H:H,"No RFID") -> 0 | C18: =COUNTIFS('Raw Data'!E:E,"Fitness",'Raw Data'!H:H,"Piloting") -> 0 | D18: =COUNTIFS('Raw Data'!E:E,"Fitness",'Raw Data'!H:H,"Partial production") -> 0 | E18: =COUNTIFS('Raw Data'!E:E,"Fitness",'Raw Data'!H:H,"Full production") -> 0 | F18: =SUM(B18:E18) -> 0
A19: Agriculture | B19: =COUNTIFS('Raw Data'!E:E,"Agriculture",'Raw Data'!H:H,"No RFID") -> 0 | C19: =COUNTIFS('Raw Data'!E:E,"Agriculture",'Raw Data'!H:H,"Piloting") -> 0 | D19: =COUNTIFS('Raw Data'!E:E,"Agriculture",'Raw Data'!H:H,"Partial production") -> 0 | E19: =COUNTIFS('Raw Data'!E:E,"Agriculture",'Raw Data'!H:H,"Full production") -> 0 | F19: =SUM(B19:E19) -> 0
A20: EU Compliance | B20: =COUNTIFS('Raw Data'!E:E,"EU Compliance",'Raw Data'!H:H,"No RFID") -> 0 | C20: =COUNTIFS('Raw Data'!E:E,"EU Compliance",'Raw Data'!H:H,"Piloting") -> 0 | D20: =COUNTIFS('Raw Data'!E:E,"EU Compliance",'Raw Data'!H:H,"Partial production") -> 0 | E20: =COUNTIFS('Raw Data'!E:E,"EU Compliance",'Raw Data'!H:H,"Full production") -> 0 | F20: =SUM(B20:E20) -> 0
A21: Automotive & Tire OEM | B21: =COUNTIFS('Raw Data'!E:E,"Automotive & Tire OEM",'Raw Data'!H:H,"No RFID") -> 0 | C21: =COUNTIFS('Raw Data'!E:E,"Automotive & Tire OEM",'Raw Data'!H:H,"Piloting") -> 0 | D21: =COUNTIFS('Raw Data'!E:E,"Automotive & Tire OEM",'Raw Data'!H:H,"Partial production") -> 0 | E21: =COUNTIFS('Raw Data'!E:E,"Automotive & Tire OEM",'Raw Data'!H:H,"Full production") -> 0 | F21: =SUM(B21:E21) -> 0
A22: Aerospace & Aviation MRO | B22: =COUNTIFS('Raw Data'!E:E,"Aerospace & Aviation MRO",'Raw Data'!H:H,"No RFID") -> 0 | C22: =COUNTIFS('Raw Data'!E:E,"Aerospace & Aviation MRO",'Raw Data'!H:H,"Piloting") -> 0 | D22: =COUNTIFS('Raw Data'!E:E,"Aerospace & Aviation MRO",'Raw Data'!H:H,"Partial production") -> 0 | E22: =COUNTIFS('Raw Data'!E:E,"Aerospace & Aviation MRO",'Raw Data'!H:H,"Full production") -> 0 | F22: =SUM(B22:E22) -> 0
A23: Data Center & IT Asset Tracking | B23: =COUNTIFS('Raw Data'!E:E,"Data Center & IT Asset Tracking",'Raw Data'!H:H,"No RFID") -> 0 | C23: =COUNTIFS('Raw Data'!E:E,"Data Center & IT Asset Tracking",'Raw Data'!H:H,"Piloting") -> 0 | D23: =COUNTIFS('Raw Data'!E:E,"Data Center & IT Asset Tracking",'Raw Data'!H:H,"Partial production") -> 0 | E23: =COUNTIFS('Raw Data'!E:E,"Data Center & IT Asset Tracking",'Raw Data'!H:H,"Full production") -> 0 | F23: =SUM(B23:E23) -> 0
A24: Government & Defense | B24: =COUNTIFS('Raw Data'!E:E,"Government & Defense",'Raw Data'!H:H,"No RFID") -> 0 | C24: =COUNTIFS('Raw Data'!E:E,"Government & Defense",'Raw Data'!H:H,"Piloting") -> 0 | D24: =COUNTIFS('Raw Data'!E:E,"Government & Defense",'Raw Data'!H:H,"Partial production") -> 0 | E24: =COUNTIFS('Raw Data'!E:E,"Government & Defense",'Raw Data'!H:H,"Full production") -> 0 | F24: =SUM(B24:E24) -> 0
A25: Cold Chain & Food Traceability | B25: =COUNTIFS('Raw Data'!E:E,"Cold Chain & Food Traceability",'Raw Data'!H:H,"No RFID") -> 0 | C25: =COUNTIFS('Raw Data'!E:E,"Cold Chain & Food Traceability",'Raw Data'!H:H,"Piloting") -> 0 | D25: =COUNTIFS('Raw Data'!E:E,"Cold Chain & Food Traceability",'Raw Data'!H:H,"Partial production") -> 0 | E25: =COUNTIFS('Raw Data'!E:E,"Cold Chain & Food Traceability",'Raw Data'!H:H,"Full production") -> 0 | F25: =SUM(B25:E25) -> 0
A28: RQ3 — KPI lift expected vs realized (across all respondents)
A29: KPI | B29: Median expected | C29: Median realized | D29: Delta (realized - expected) | E29: Source columns
A30: Inventory accuracy lift (pp) | B30: =IFERROR(MEDIAN('raw data'!index('Raw Data'!4:1000,0,MATCH("Q14_inv_acc",'Raw Data'!3:3,0))),"[map column]") -> [map column] | C30: [fill after import] | D30: =IFERROR(C30-B30,"") | E30: Q14 Q14_inv_acc / Q15 Q15_inv_acc
A31: BOPIS lift (pp) | B31: =IFERROR(MEDIAN('raw data'!index('Raw Data'!4:1000,0,MATCH("Q14_bopis",'Raw Data'!3:3,0))),"[map column]") -> [map column] | C31: [fill after import] | D31: =IFERROR(C31-B31,"") | E31: Q14 Q14_bopis / Q15 Q15_bopis
A32: Shrink reduction (pp) | B32: =IFERROR(MEDIAN('raw data'!index('Raw Data'!4:1000,0,MATCH("Q14_shrink",'Raw Data'!3:3,0))),"[map column]") -> [map column] | C32: [fill after import] | D32: =IFERROR(C32-B32,"") | E32: Q14 Q14_shrink / Q15 Q15_shrink
A33: Labor reduction (pp) | B33: =IFERROR(MEDIAN('raw data'!index('Raw Data'!4:1000,0,MATCH("Q14_labor",'Raw Data'!3:3,0))),"[map column]") -> [map column] | C33: [fill after import] | D33: =IFERROR(C33-B33,"") | E33: Q14 Q14_labor / Q15 Q15_labor
A34: Fines reduction ($K) | B34: =IFERROR(MEDIAN('raw data'!index('Raw Data'!4:1000,0,MATCH("Q14_fines",'Raw Data'!3:3,0))),"[map column]") -> [map column] | C34: [fill after import] | D34: =IFERROR(C34-B34,"") | E34: Q14 Q14_fines / Q15 Q15_fines
A35: CSAT lift (pp) | B35: =IFERROR(MEDIAN('raw data'!index('Raw Data'!4:1000,0,MATCH("Q14_csat",'Raw Data'!3:3,0))),"[map column]") -> [map column] | C35: [fill after import] | D35: =IFERROR(C35-B35,"") | E35: Q14 Q14_csat / Q15 Q15_csat

Sheet Dashboard
A1: Top-line dashboard — 2026 RFID Industry Adoption Index
A2: Live formulas pull from Raw Data. Numbers populate after fieldwork close.
A3: Total completed responses | B3: Target | C3: % to goal | D3: Industries with N>=10
A4: ='Respondent DB'!B6 -> 0 | B4: =200 -> 200 | C4: =IFERROR(B4/C4, 0) -> 0 | D4: =COUNTIF('Respondent DB'!N11:N30, ">=10") -> 0
A7: Adoption stage distribution by industry (% of completed)
A8: Industry | B8: No RFID | C8: Piloting | D8: Partial production | E8: Full production
A9: Retail & Apparel | B9: =IFERROR('Analysis Cross-tabs'!B6/'Analysis Cross-tabs'!F6,0) -> 0 | C9: =IFERROR('Analysis Cross-tabs'!C6/'Analysis Cross-tabs'!F6,0) -> 0 | D9: =IFERROR('Analysis Cross-tabs'!D6/'Analysis Cross-tabs'!F6,0) -> 0 | E9: =IFERROR('Analysis Cross-tabs'!E6/'Analysis Cross-tabs'!F6,0) -> 0
A10: Hospitality | B10: =IFERROR('Analysis Cross-tabs'!B7/'Analysis Cross-tabs'!F7,0) -> 0 | C10: =IFERROR('Analysis Cross-tabs'!C7/'Analysis Cross-tabs'!F7,0) -> 0 | D10: =IFERROR('Analysis Cross-tabs'!D7/'Analysis Cross-tabs'!F7,0) -> 0 | E10: =IFERROR('Analysis Cross-tabs'!E7/'Analysis Cross-tabs'!F7,0) -> 0
A11: Healthcare | B11: =IFERROR('Analysis Cross-tabs'!B8/'Analysis Cross-tabs'!F8,0) -> 0 | C11: =IFERROR('Analysis Cross-tabs'!C8/'Analysis Cross-tabs'!F8,0) -> 0 | D11: =IFERROR('Analysis Cross-tabs'!D8/'Analysis Cross-tabs'!F8,0) -> 0 | E11: =IFERROR('Analysis Cross-tabs'!E8/'Analysis Cross-tabs'!F8,0) -> 0
A12: Events & Venues | B12: =IFERROR('Analysis Cross-tabs'!B9/'Analysis Cross-tabs'!F9,0) -> 0 | C12: =IFERROR('Analysis Cross-tabs'!C9/'Analysis Cross-tabs'!F9,0) -> 0 | D12: =IFERROR('Analysis Cross-tabs'!D9/'Analysis Cross-tabs'!F9,0) -> 0 | E12: =IFERROR('Analysis Cross-tabs'!E9/'Analysis Cross-tabs'!F9,0) -> 0
A13: Logistics | B13: =IFERROR('Analysis Cross-tabs'!B10/'Analysis Cross-tabs'!F10,0) -> 0 | C13: =IFERROR('Analysis Cross-tabs'!C10/'Analysis Cross-tabs'!F10,0) -> 0 | D13: =IFERROR('Analysis Cross-tabs'!D10/'Analysis Cross-tabs'!F10,0) -> 0 | E13: =IFERROR('Analysis Cross-tabs'!E10/'Analysis Cross-tabs'!F10,0) -> 0
A14: Industrial | B14: =IFERROR('Analysis Cross-tabs'!B11/'Analysis Cross-tabs'!F11,0) -> 0 | C14: =IFERROR('Analysis Cross-tabs'!C11/'Analysis Cross-tabs'!F11,0) -> 0 | D14: =IFERROR('Analysis Cross-tabs'!D11/'Analysis Cross-tabs'!F11,0) -> 0 | E14: =IFERROR('Analysis Cross-tabs'!E11/'Analysis Cross-tabs'!F11,0) -> 0
A15: Libraries | B15: =IFERROR('Analysis Cross-tabs'!B12/'Analysis Cross-tabs'!F12,0) -> 0 | C15: =IFERROR('Analysis Cross-tabs'!C12/'Analysis Cross-tabs'!F12,0) -> 0 | D15: =IFERROR('Analysis Cross-tabs'!D12/'Analysis Cross-tabs'!F12,0) -> 0 | E15: =IFERROR('Analysis Cross-tabs'!E12/'Analysis Cross-tabs'!F12,0) -> 0
A16: Laundry Services | B16: =IFERROR('Analysis Cross-tabs'!B13/'Analysis Cross-tabs'!F13,0) -> 0 | C16: =IFERROR('Analysis Cross-tabs'!C13/'Analysis Cross-tabs'!F13,0) -> 0 | D16: =IFERROR('Analysis Cross-tabs'!D13/'Analysis Cross-tabs'!F13,0) -> 0 | E16: =IFERROR('Analysis Cross-tabs'!E13/'Analysis Cross-tabs'!F13,0) -> 0
A17: Pharmaceutical | B17: =IFERROR('Analysis Cross-tabs'!B14/'Analysis Cross-tabs'!F14,0) -> 0 | C17: =IFERROR('Analysis Cross-tabs'!C14/'Analysis Cross-tabs'!F14,0) -> 0 | D17: =IFERROR('Analysis Cross-tabs'!D14/'Analysis Cross-tabs'!F14,0) -> 0 | E17: =IFERROR('Analysis Cross-tabs'!E14/'Analysis Cross-tabs'!F14,0) -> 0
A18: Luxury Brands | B18: =IFERROR('Analysis Cross-tabs'!B15/'Analysis Cross-tabs'!F15,0) -> 0 | C18: =IFERROR('Analysis Cross-tabs'!C15/'Analysis Cross-tabs'!F15,0) -> 0 | D18: =IFERROR('Analysis Cross-tabs'!D15/'Analysis Cross-tabs'!F15,0) -> 0 | E18: =IFERROR('Analysis Cross-tabs'!E15/'Analysis Cross-tabs'!F15,0) -> 0
A19: Brand Protection | B19: =IFERROR('Analysis Cross-tabs'!B16/'Analysis Cross-tabs'!F16,0) -> 0 | C19: =IFERROR('Analysis Cross-tabs'!C16/'Analysis Cross-tabs'!F16,0) -> 0 | D19: =IFERROR('Analysis Cross-tabs'!D16/'Analysis Cross-tabs'!F16,0) -> 0 | E19: =IFERROR('Analysis Cross-tabs'!E16/'Analysis Cross-tabs'!F16,0) -> 0
A20: Education | B20: =IFERROR('Analysis Cross-tabs'!B17/'Analysis Cross-tabs'!F17,0) -> 0 | C20: =IFERROR('Analysis Cross-tabs'!C17/'Analysis Cross-tabs'!F17,0) -> 0 | D20: =IFERROR('Analysis Cross-tabs'!D17/'Analysis Cross-tabs'!F17,0) -> 0 | E20: =IFERROR('Analysis Cross-tabs'!E17/'Analysis Cross-tabs'!F17,0) -> 0
... A28: Cold Chain & Food Traceability | B28: =IFERROR('Analysis Cross-tabs'!B25/'Analysis Cross-tabs'!F25,0) -> 0 | C28: =IFERROR('Analysis Cross-tabs'!C25/'Analysis Cross-tabs'!F25,0) -> 0 | D28: =IFERROR('Analysis Cross-tabs'!D25/'Analysis Cross-tabs'!F25,0) -> 0 | E28: =IFERROR('Analysis Cross-tabs'!E25/'Analysis Cross-tabs'!F25,0) -> 0

Sheet Methodology Metadata
A1: Methodology metadata — final values copy into the report appendix.
A3: Study | B3: Proud Tek 2026 RFID Industry Adoption Index
A4: Pre-registered | B4: 2026-05-11 (Center for Open Science)
A5: Target N | B5: 200
A6: Industries | B6: 20
A7: Per-industry quota | B7: 10
A8: Recruitment opens | B8: 2026-05-18
A9: Pilot fielded | B9: 2026-06-01 (N=20)
A10: Main field opens | B10: 2026-06-15
A11: Fieldwork closes (target) | B11: 2026-08-15
A12: Data freeze | B12: 2026-09-05
A13: First data brief | B13: 2026-09-15
A14: Full report | B14: 2026-10-30
A15: Open dataset (CC-BY-4.0) | B15: 2027-01-28
A16: Weighting target | B16: IDC Worldwide RFID Forecast 2026 (or latest available)
A17: Weight cells | B17: Industry × organization-size band; collapse <3
A18: Reliability target | B18: Cronbach α ≥ 0.75 on Likert KPI batteries
A19: Inter-rater target | B19: Cohen κ ≥ 0.70 on qualitative coding
A20: Multiple-comparisons correction | B20: Bonferroni for 5 primary hypotheses; per-comparison α = 0.01
A21: Bootstrap iterations for CIs | B21: 10000
A22: Random seed | B22: 42
A23: Funding | B23: Proud Tek internal marketing R&D, USD 28,500
A24: Conflicts of interest | B24: Researchers and statistical adviser hold no Proud Tek equity
A25: Open data license | B25: CC-BY-4.0 after 90-day exclusivity window
A26: Analysis code repository | B26: github.com/Proud-Tek/research-2026-adoption-index
